const ErrorResponse = require('../utils/errorResponse');

const errorHandler = (err, req, res, next) => {
  console.error(err.stack.red);

  let error = { ...err };
  error.message = err.message;

  // Mongoose bad ObjectId (404)
  if (err.name === 'CastError') {
    const message = `Resource not found`;
    error = new ErrorResponse(message, 404);
  }

  // Mongoose duplicate key (400)
  if (err.code === 11000) {
    const message = 'Duplicate field value entered';
    error = new ErrorResponse(message, 400);
  }

  // Mongoose validation error (400)
  if (err.name === 'ValidationError') {
    const message = Object.values(err.errors).map(val => val.message);
    error = new ErrorResponse(message, 400);
  }

  // JWT invalid token (401)
  if (err.name === 'JsonWebTokenError') {
    const message = 'Invalid token';
    error = new ErrorResponse(message, 401);
  }

  // JWT expired (401)
  if (err.name === 'TokenExpiredError') {
    const message = 'Token expired';
    error = new ErrorResponse(message, 401);
  }

  // Role-based access error (403)
  // Note: The `authorize` middleware in auth.js already throws an ErrorResponse,
  // so this is just for clarity. Your existing handler already catches it!
  if (err.statusCode === 403) {
    error = new ErrorResponse(err.message, 403);
  }

  res.status(error.statusCode || 500).json({
    success: false,
    error: error.message || 'Server Error',
  });
};

module.exports = errorHandler;